<?xml version="1.0" encoding="utf-8"?>
<!-- This URDF was automatically created by SolidWorks to URDF Exporter! Originally created by Stephen Brawner (brawner@gmail.com) 
     Commit Version: 1.6.0-4-g7f85cfe  Build Version: 1.6.7995.38578
     For more information, please see http://wiki.ros.org/sw_urdf_exporter -->
     
     
<robot
  name="larvabot" xmlns:xacro="http://www.ros.org/wiki/xacro">>
  <!-- Constants for robot dimensions -->
  <xacro:property name="PI" value="3.1415926535897931"/>
  <xacro:property name="camera_link" value="0.01" /> <!-- Size of square 'camera' box -->
  <!-- Import all Gazebo-customization elements, including Gazebo colors -->
  <xacro:include filename="$(find larvabot_description)/urdf/larvabot.gazebo" />
  <!-- Import Rviz colors -->
  <xacro:include filename="$(find larvabot_description)/urdf/materials.xacro" />

  <!-- Used for fixing robot to Gazebo 'base_link' -->
  <!--
  <link name="world"/>

  <joint name="floating" type="floating">
    <parent link="world"/>
    <child link="base_link"/>
  </joint>-->

  <link
    name="base_link">
    <inertial>
      <origin
        xyz="-3.4694E-17 0 0.036491"
        rpy="0 0 0" />
      <mass
        value="0.57939" />
      <inertia
        ixx="0.00048537"
        ixy="-5.948E-20"
        ixz="1.1695E-20"
        iyy="0.0022234"
        iyz="3.9398E-20"
        izz="0.0022032" />
    </inertial>
    <visual>
      <origin
        xyz="0 0 0"
        rpy="0 0 0" />
      <geometry>
        <mesh
          filename="package://larvabot_description/meshes/base_link.STL" />
      </geometry>
      <material
        name="">
        <color
          rgba="0.69804 0.69804 0.69804 1" />
      </material>
    </visual>
    <collision>
      <origin
        xyz="0 0 0"
        rpy="0 0 0" />
      <geometry>
        <mesh
          filename="package://larvabot_description/meshes/base_link.STL" />
      </geometry>
    </collision>
  </link>
  <link
    name="prismBall11">
    <inertial>
      <origin
        xyz="0.0323762886597938 -5.55111512312578E-17 -1.11022302462516E-16"
        rpy="0 0 0" />
      <mass
        value="0.0115189636236523" />
      <inertia
        ixx="5.64072960952047E-07"
        ixy="-3.74172375430286E-39"
        ixz="1.51675810324979E-23"
        iyy="4.32771803305125E-06"
        iyz="1.45391056731556E-39"
        izz="4.32771803305125E-06" />
    </inertial>
    <visual>
      <origin
        xyz="0 0 0"
        rpy="0 0 0" />
      <geometry>
        <mesh
          filename="package://larvabot_description/meshes/prismBall11.STL" />
      </geometry>
      <material
        name="">
        <color
          rgba="0.698039215686274 0.698039215686274 0.698039215686274 1" />
      </material>
    </visual>
    <collision>
      <origin
        xyz="0 0 0"
        rpy="0 0 0" />
      <geometry>
        <mesh
          filename="package://larvabot_description/meshes/prismBall11.STL" />
      </geometry>
    </collision>
  </link>
  <joint
    name="prism11"
    type="prismatic">
    <origin
      xyz="0.101 0 0.0365"
      rpy="0 0 0" />
    <parent
      link="base_link" />
    <child
      link="prismBall11" />
    <axis
      xyz="1 0 0" />
    <limit
      lower="-0.3"
      upper="0"
      effort="100"
      velocity="100" />
  </joint>
  <link
    name="ball11">
    <inertial>
      <origin
        xyz="-2.77555756156289E-17 5.55111512312578E-17 0"
        rpy="0 0 0" />
      <mass
        value="0.00237504404611388" />
      <inertia
        ixx="9.50017618445554E-08"
        ixy="0"
        ixz="0"
        iyy="9.50017618445554E-08"
        iyz="4.53527358276946E-40"
        izz="9.50017618445554E-08" />
    </inertial>
    <visual>
      <origin
        xyz="0 0 0"
        rpy="0 0 0" />
      <geometry>
        <mesh
          filename="package://larvabot_description/meshes/ball11.STL" />
      </geometry>
      <material
        name="">
        <color
          rgba="0.698039215686274 0.698039215686274 0.698039215686274 1" />
      </material>
    </visual>
    <collision>
      <origin
        xyz="0 0 0"
        rpy="0 0 0" />
      <geometry>
        <mesh
          filename="package://larvabot_description/meshes/ball11.STL" />
      </geometry>
    </collision>
  </link>
  <joint
    name="Ball11"
    type="revolute">
    <origin
      xyz="0.078 0 0"
      rpy="0 0 0" />
    <parent
      link="prismBall11" />
    <child
      link="ball11" />
    <axis
      xyz="0 -1 0" />
    <limit
      lower="-1"
      upper="1"
      effort="100"
      velocity="100" />
  </joint>
  <link
    name="ball12">
    <inertial>
      <origin
        xyz="0.0456237113402061 5.55111512312578E-17 0"
        rpy="0 0 0" />
      <mass
        value="0.0115189636236523" />
      <inertia
        ixx="5.64072960952047E-07"
        ixy="3.74172375430286E-39"
        ixz="8.65197208612331E-23"
        iyy="4.32771803305125E-06"
        iyz="-1.45391056731556E-39"
        izz="4.32771803305125E-06" />
    </inertial>
    <visual>
      <origin
        xyz="0 0 0"
        rpy="0 0 0" />
      <geometry>
        <mesh
          filename="package://larvabot_description/meshes/ball12.STL" />
      </geometry>
      <material
        name="">
        <color
          rgba="0.698039215686274 0.698039215686274 0.698039215686274 1" />
      </material>
    </visual>
    <collision>
      <origin
        xyz="0 0 0"
        rpy="0 0 0" />
      <geometry>
        <mesh
          filename="package://larvabot_description/meshes/ball12.STL" />
      </geometry>
    </collision>
  </link>
  <joint
    name="Ball12"
    type="revolute">
    <origin
      xyz="0 0 0"
      rpy="0 0 0" />
    <parent
      link="ball11" />
    <child
      link="ball12" />
    <axis
      xyz="0 0 1" />
    <limit
      lower="-1"
      upper="1"
      effort="100"
      velocity="100" />
  </joint>
  <link
    name="prismBall12">
    <inertial>
      <origin
        xyz="0.03295 -4.1633E-17 2.7756E-17"
        rpy="0 0 0" />
      <mass
        value="0.18762" />
      <inertia
        ixx="0.00015223"
        ixy="-2.7031E-21"
        ixz="4.0242E-21"
        iyy="0.00014166"
        iyz="-5.6844E-21"
        izz="0.0001337" />
    </inertial>
    <visual>
      <origin
        xyz="0 0 0"
        rpy="0 0 0" />
      <geometry>
        <mesh
          filename="package://larvabot_description/meshes/prismBall12.STL" />
      </geometry>
      <material
        name="">
        <color
          rgba="0.69804 0.69804 0.69804 1" />
      </material>
    </visual>
    <collision>
      <origin
        xyz="0 0 0"
        rpy="0 0 0" />
      <geometry>
        <mesh
          filename="package://larvabot_description/meshes/prismBall12.STL" />
      </geometry>
    </collision>
  </link>
  <joint
    name="prism12"
    type="prismatic">
    <origin
      xyz="0.078 0 0"
      rpy="0 0 0" />
    <parent
      link="ball12" />
    <child
      link="prismBall12" />
    <axis
      xyz="1 0 0" />
    <limit
      lower="-0.3"
      upper="0"
      effort="100"
      velocity="100" />
  </joint>
  <link
    name="end1">
    <inertial>
      <origin
        xyz="-1.3878E-17 -0.041187 5.5511E-17"
        rpy="0 0 0" />
      <mass
        value="0.15603" />
      <inertia
        ixx="0.0001081"
        ixy="-1.8651E-20"
        ixz="8.6164E-22"
        iyy="0.00010789"
        iyz="5.4728E-21"
        izz="0.00010981" />
    </inertial>
    <visual>
      <origin
        xyz="0 0 0"
        rpy="0 0 0" />
      <geometry>
        <mesh
          filename="package://larvabot_description/meshes/end1.STL" />
      </geometry>
      <material
        name="">
        <color
          rgba="0.69804 0.69804 0.69804 1" />
      </material>
    </visual>
    <collision>
      <origin
        xyz="0 0 0"
        rpy="0 0 0" />
      <geometry>
        <mesh
          filename="package://larvabot_description/meshes/end1.STL" />
      </geometry>
    </collision>
  </link>
  <joint
    name="End1"
    type="revolute">
    <origin
      xyz="0.084 0 0"
      rpy="0 0 1.5708" />
    <parent
      link="prismBall12" />
    <child
      link="end1" />
    <axis
      xyz="1 0 0" />
    <limit
      lower="-1"
      upper="1"
      effort="100"
      velocity="100" />
  </joint>
  <link
    name="prismBall21">
    <inertial>
      <origin
        xyz="-0.0323762886597938 1.38777878078145E-17 0"
        rpy="0 0 0" />
      <mass
        value="0.0115189636236523" />
      <inertia
        ixx="5.64072960952047E-07"
        ixy="3.29998317785006E-40"
        ixz="-1.51675810324979E-23"
        iyy="4.32771803305125E-06"
        iyz="8.25138565718054E-41"
        izz="4.32771803305125E-06" />
    </inertial>
    <visual>
      <origin
        xyz="0 0 0"
        rpy="0 0 0" />
      <geometry>
        <mesh
          filename="package://larvabot_description/meshes/prismBall21.STL" />
      </geometry>
      <material
        name="">
        <color
          rgba="0.698039215686274 0.698039215686274 0.698039215686274 1" />
      </material>
    </visual>
    <collision>
      <origin
        xyz="0 0 0"
        rpy="0 0 0" />
      <geometry>
        <mesh
          filename="package://larvabot_description/meshes/prismBall21.STL" />
      </geometry>
    </collision>
  </link>
  <joint
    name="prism21"
    type="prismatic">
    <origin
      xyz="-0.101 0 0.0365"
      rpy="0 0 0" />
    <parent
      link="base_link" />
    <child
      link="prismBall21" />
    <axis
      xyz="-1 0 0" />
    <limit
      lower="-0.3"
      upper="0"
      effort="100"
      velocity="100" />
  </joint>
  <link
    name="ball21">
    <inertial>
      <origin
        xyz="2.77555756156289E-17 1.38777878078145E-17 0"
        rpy="0 0 0" />
      <mass
        value="0.00237504404611388" />
      <inertia
        ixx="9.50017618445554E-08"
        ixy="-4.5164155680605E-56"
        ixz="0"
        iyy="9.50017618445554E-08"
        iyz="-4.53527358276946E-40"
        izz="9.50017618445554E-08" />
    </inertial>
    <visual>
      <origin
        xyz="0 0 0"
        rpy="0 0 0" />
      <geometry>
        <mesh
          filename="package://larvabot_description/meshes/ball21.STL" />
      </geometry>
      <material
        name="">
        <color
          rgba="0.698039215686274 0.698039215686274 0.698039215686274 1" />
      </material>
    </visual>
    <collision>
      <origin
        xyz="0 0 0"
        rpy="0 0 0" />
      <geometry>
        <mesh
          filename="package://larvabot_description/meshes/ball21.STL" />
      </geometry>
    </collision>
  </link>
  <joint
    name="Ball21"
    type="revolute">
    <origin
      xyz="-0.078 0 0"
      rpy="0 0 0" />
    <parent
      link="prismBall21" />
    <child
      link="ball21" />
    <axis
      xyz="0 1 0" />
    <limit
      lower="-1"
      upper="1"
      effort="100"
      velocity="100" />
  </joint>
  <link
    name="ball22">
    <inertial>
      <origin
        xyz="-0.0456237113402061 -2.77555756156289E-17 2.77555756156289E-17"
        rpy="0 0 0" />
      <mass
        value="0.0115189636236523" />
      <inertia
        ixx="5.64072960952047E-07"
        ixy="-6.19297408492045E-39"
        ixz="-8.32055025206996E-23"
        iyy="4.32771803305125E-06"
        iyz="-2.46598966803581E-38"
        izz="4.32771803305125E-06" />
    </inertial>
    <visual>
      <origin
        xyz="0 0 0"
        rpy="0 0 0" />
      <geometry>
        <mesh
          filename="package://larvabot_description/meshes/ball22.STL" />
      </geometry>
      <material
        name="">
        <color
          rgba="0.698039215686274 0.698039215686274 0.698039215686274 1" />
      </material>
    </visual>
    <collision>
      <origin
        xyz="0 0 0"
        rpy="0 0 0" />
      <geometry>
        <mesh
          filename="package://larvabot_description/meshes/ball22.STL" />
      </geometry>
    </collision>
  </link>
  <joint
    name="Ball22"
    type="revolute">
    <origin
      xyz="0 0 0"
      rpy="0 0 0" />
    <parent
      link="ball21" />
    <child
      link="ball22" />
    <axis
      xyz="0 0 1" />
    <limit
      lower="-1"
      upper="1"
      effort="100"
      velocity="100" />
  </joint>
  <link
    name="prismBall22">
    <inertial>
      <origin
        xyz="-0.0329499967097806 0 1.60559317718967E-05"
        rpy="0 0 0" />
      <mass
        value="0.187624271832945" />
      <inertia
        ixx="0.000152229382733039"
        ixy="-2.08301025777027E-21"
        ixz="6.51957077548245E-22"
        iyy="0.000141661354216007"
        iyz="3.6271825121918E-21"
        izz="0.00013370351718186" />
    </inertial>
    <visual>
      <origin
        xyz="0 0 0"
        rpy="0 0 0" />
      <geometry>
        <mesh
          filename="package://larvabot_description/meshes/prismBall22.STL" />
      </geometry>
      <material
        name="">
        <color
          rgba="0.698039215686274 0.698039215686274 0.698039215686274 1" />
      </material>
    </visual>
    <collision>
      <origin
        xyz="0 0 0"
        rpy="0 0 0" />
      <geometry>
        <mesh
          filename="package://larvabot_description/meshes/prismBall22.STL" />
      </geometry>
    </collision>
  </link>
  <joint
    name="prism22"
    type="prismatic">
    <origin
      xyz="-0.078 0 0"
      rpy="0 0 0" />
    <parent
      link="ball22" />
    <child
      link="prismBall22" />
    <axis
      xyz="-1 0 0" />
    <limit
      lower="-0.3"
      upper="0"
      effort="100"
      velocity="100" />
  </joint>
  <link
    name="end2">
    <inertial>
      <origin
        xyz="-1.38777878078145E-17 2.77555756156289E-17 0.041187171670794"
        rpy="0 0 0" />
      <mass
        value="0.156030185058769" />
      <inertia
        ixx="0.000108104635725743"
        ixy="-5.55308251651962E-21"
        ixz="2.1032120409548E-20"
        iyy="0.000109805700457356"
        iyz="-7.60978608975547E-21"
        izz="0.000107890465752551" />
    </inertial>
    <visual>
      <origin
        xyz="0 0 0"
        rpy="0 0 0" />
      <geometry>
        <mesh
          filename="package://larvabot_description/meshes/end2.STL" />
      </geometry>
      <material name="red"/>
        
    </visual>
    <collision>
      <origin
        xyz="0 0 0"
        rpy="0 0 0" />
      <geometry>
        <mesh
          filename="package://larvabot_description/meshes/end2.STL" />
      </geometry>
    </collision>
  </link>
  <joint
    name="End2"
    type="revolute">
    <origin
      xyz="-0.084 0 0.0005"
      rpy="1.5708 0 -1.5708" />
    <parent
      link="prismBall22" />
    <child
      link="end2" />
    <axis
      xyz="1 0 0" />
    <limit
      lower="-1"
      upper="1"
      effort="100"
      velocity="100" />
  </joint>

  <!-- Camera -->
  <joint name="camera_joint" type="fixed">
    <origin xyz="0.02 -0.08 0" rpy="0 0 0"/>
    <parent link="end1"/>
    <child link="camera_link"/>
  </joint>

  <link name="camera_link">
    <collision>
      <origin xyz="0 0 0" rpy="0 0 0"/>
      <geometry>
	      <box size="${camera_link} ${camera_link} ${camera_link}"/>
      </geometry>
    </collision>

    <visual>
      <origin xyz="0 0 0" rpy="0 0 0"/>
      <geometry>
	      <box size="${camera_link} ${camera_link} ${camera_link}"/>
      </geometry>
      <material name="red"/>
    </visual>

    <inertial>
      <mass value="1e-5" />
      <origin xyz="0 0 0" rpy="0 0 0"/>
      <inertia ixx="1e-6" ixy="0" ixz="0" iyy="1e-6" iyz="0" izz="1e-6" />
    </inertial>
  </link>

  <joint name="camera_optical_joint" type="fixed">
    <!-- these values have to be these values otherwise the gazebo camera image
        won't be aligned properly with the frame it is supposedly originating from -->
    <origin xyz="0 0 0" rpy="${-pi/2} 0 ${-pi/2}"/>
    <parent link="camera_link"/>
    <child link="camera_link_optical"/>
  </joint>

  <link name="camera_link_optical">
  </link>

  <!-- Laser -->
  <joint name="laser_joint" type="fixed">
    <origin xyz="-0.02 -0.08 0" rpy="0 0 0"/>
    <parent link="end1"/>
    <child link="laser_link"/>
  </joint>

  <link name="laser_link">
    <collision>
      <origin xyz="0 0 0" rpy="0 0 0"/>
      <geometry>
	      <box size="${camera_link} ${camera_link} ${camera_link}"/>
      </geometry>
    </collision>

    <visual>
      <origin xyz="0 0 0" rpy="0 0 0"/>
      <geometry>
	      <box size="${camera_link} ${camera_link} ${camera_link}"/>
      </geometry>
      <material name="red"/>
    </visual>

    <inertial>
      <mass value="1e-5" />
      <origin xyz="0 0 0" rpy="0 0 0"/>
      <inertia ixx="1e-6" ixy="0" ixz="0" iyy="1e-6" iyz="0" izz="1e-6" />
    </inertial>
  </link>

  <!-- imu1 -->
  <joint name="imu_joint" type="fixed">
    <origin xyz="0 -0.04 0.035" rpy="0 0 0"/>
    <parent link="end1"/>
    <child link="imu_link"/>
  </joint>

  <link name="imu_link">
    <collision>
      <origin xyz="0 0 0" rpy="0 0 0"/>
      <geometry>
	      <box size="${camera_link} ${camera_link} ${camera_link}"/>
      </geometry>
    </collision>

    <visual>
      <origin xyz="0 0 0" rpy="0 0 0"/>
      <geometry>
	      <box size="${camera_link} ${camera_link} ${camera_link}"/>
      </geometry>
      <material name="red"/>
    </visual>

    <inertial>
      <mass value="1e-5" />
      <origin xyz="0 0 0" rpy="0 0 0"/>
      <inertia ixx="1e-6" ixy="0" ixz="0" iyy="1e-6" iyz="0" izz="1e-6" />
    </inertial>
  </link>






</robot>
